Workbook

Sheet APPLICATION
G2: Nueva Vizcaya
G3: Solano | X3: 2026 | AC3: -
F4: BERNADETTE T. SAMANDRE
F5: 4 | G5: February | L5: 2026
A6: =+U8 -> 0 | F6: =+U9 -> 0 | H6: =+U10 -> 0 | R6: =+B8 -> 0 | V6: =+B9 -> 0 | Y6: =+B10 -> 0
M15: =+L12 -> 0
B18: N/A | U18: N/A
B21: None | U21: None
L22: =+B10 -> 0 | AC22: =+U10 -> 0
B23: =+H13 -> 0 | U23: =+Z13 -> 0
B25: =+B15 -> 0 | M25: =+M15 -> 0 | U25: =+U15 -> 0 | AF25: =+AF15 -> 0
K26: =+B9 -> 0 | AD26: =+U9 -> 0
B27: =+H13 -> 0 | U27: Filipino
B29: =+B15 -> 0 | M29: =+M15 -> 0 | U29: =+U25 -> 0 | AF29: =+AF25 -> 0
B30: =+B26 -> 0 | H30: =+K26 -> 0 | L30: =+L22 -> 0 | U30: =+U26 -> 0 | Y30: =+AD26 -> 0 | AD30: =+AC22 -> 0
B32: Filipino | U32: Filipino
B34: =+B29 -> 0 | M34: =+M29 -> 0 | U34: =+U29 -> 0 | AF34: =+AF29 -> 0
U37: =+B37 -> 0 | W37: =+E37 -> 0 | AD37: =+L37 -> 0
B38: Solano, Nueva Vizcaya | U38: Solano, Nueva Vizcaya
B42: OLIVER V. CATAHINA | U42: OLIVER V. CATAHINA

Sheet CONSENT F
A1: Municipal Form No. 92
A3: Republic of the Philippines
A4: Province of Nueva Vizcaya
A5: Municipality of Solano
A8: CONSENT TO MARRIAGE OF A PERSON UNDERAGE
A10: For FEMALE
A12: Municipality | F12: : | G12: SOLANO | Q12: Province | U12: : | V12: NUEVA VIZCAYA
B14: I/We | D14: =+APPLICATION!U30 -> 0 | L14: =+APPLICATION!AD30 -> 0 | S14: and | U14: n/a
A15: resident/s of | G15: =+APPLICATION!U34 -> 0
A16: =+APPLICATION!U31 -> 0 | G16: and | I16: n/a | O16: of | Q16: =+APPLICATION!U8 -> 0 | AA16: =+APPLICATION!U10 -> 0
A17: who is a resident of | H17: =+APPLICATION!U15 -> 0 | AA17: , | AB17: single, eighteen and
A18: less than twenty one years of age, after being duly sworn to in accordance with law do hereby state
A19: that I/we am/are freely giving my/our consent to my/our child/ward | W19: =+Q16 -> 0 | AD19: =+AA16 -> 0
A20: who is marrying with | I20: =+APPLICATION!B8 -> 0 | S20: =+APPLICATION!B10 -> 0 | Z20: who is presently residing
A21: in | B21: =+APPLICATION!B15 -> 0 | S21: . | T21: And that I/we know of no legal impediment
A22: to such marriage and swear to the correctness of the lawful age of my/our child/ward as stated in
A23: their application for their marriage license.
T27: =+D14 -> 0 | AB27: =+L14 -> 0
T28: =+A16 -> 0
T29: 4Ps ID 025013021-5666-00073
A32: WITNESSES – (not necessary if this affidavit is subscribed before the Municipal Civil Registrar)
C37: Subscribed and sworn to before me this | Q37: =TODAY() -> 46083 | Y37: at Solano, Nueva Vizcaya,
A38: Philippines.
A41: OLIVER V. CATAHINA
A42: Municipal Civil Registrar
A44: Exempt from documentary stamp tax

Sheet CONSENT M
A1: Municipal Form No. 92
A3: Republic of the Philippines
A4: Province of Nueva Vizcaya
A5: Municipality of Solano
A8: CONSENT TO MARRIAGE OF A PERSON UNDERAGE
A10: For MALE
A12: Municipality | F12: : | G12: SOLANO | Q12: Province | U12: : | V12: NUEVA VIZCAYA
B14: I/We | D14: =+APPLICATION!B30 -> 0 | L14: =+APPLICATION!L30 -> 0 | S14: and | U14: n/a
A15: resident/s of | G15: =+APPLICATION!B34 -> 0
A16: =+APPLICATION!B31 -> 0 | G16: and | I16: n/a | O16: of | Q16: =+APPLICATION!B8 -> 0 | Z16: =+APPLICATION!B10 -> 0
A17: who is a resident of | I17: =+APPLICATION!B15 -> 0 | AA17: , | AB17: single, eighteen and
A18: less than twenty one years of age, after being duly sworn to in accordance with law do hereby state
A19: that I/we am/are freely giving my/our consent to my/our child/ward | W19: =+Q16 -> 0 | AC19: =+Z16 -> 0
A20: who is marrying with | I20: =+APPLICATION!U8 -> 0 | R20: =+APPLICATION!U10 -> 0 | Z20: who is presently residing
A21: in | B21: =+APPLICATION!U15 -> 0 | S21: . | T21: And that I/we know of no legal impediment
A22: to such marriage and swear to the correctness of the lawful age of my/our child/ward as stated in
A23: their application for their marriage license.
T27: =+D14 -> 0 | AB27: =+L14 -> 0
T28: =+A16 -> 0
A32: WITNESSES – (not necessary if this affidavit is subscribed before the Municipal Civil Registrar)
C37: Subscribed and sworn to before me this | Q37: =TODAY() -> 46083 | Y37: at Solano, Nueva Vizcaya,
A38: Philippines.
A41: OLIVER V. CATAHINA
A42: Municipal Civil Registrar
A44: Exempt from documentary stamp tax

Sheet CONSENT M&F
A1: Municipal Form No. 92
A2: Republic of the Philippines
A3: Province of Nueva Vizcaya
A4: Municipality of Solano
A6: CONSENT TO MARRIAGE OF A PERSON UNDERAGE
A8: For MALE
A10: Municipality | F10: : | G10: SOLANO | Q10: Province | U10: : | V10: NUEVA VIZCAYA
B12: I/We | D12: =+APPLICATION!B30 -> 0 | L12: =+APPLICATION!L30 -> 0 | S12: and | U12: n/a
A13: resident/s of | G13: =+APPLICATION!B34 -> 0
A14: =+APPLICATION!B31 -> 0 | G14: and | I14: n/a | O14: of | Q14: =+APPLICATION!B8 -> 0 | Z14: =+APPLICATION!B10 -> 0
A15: who is a resident of | I15: =+APPLICATION!B15 -> 0 | AA15: , | AB15: single, eighteen and
A16: less than twenty one years of age, after being duly sworn to in accordance with law do hereby state
A17: that I/we am/are freely giving my/our consent to my/our child/ward | W17: =+Q14 -> 0 | AC17: =+Z14 -> 0
A18: who is marrying with | I18: =+APPLICATION!U8 -> 0 | R18: =+APPLICATION!U10 -> 0 | Z18: who is presently residing
A19: in | B19: =+APPLICATION!U15 -> 0 | S19: . | T19: And that I/we know of no legal impediment
A20: to such marriage and swear to the correctness of the lawful age of my/our child/ward as stated in
A21: their application for their marriage license.
T23: =+D12 -> 0 | AB23: =+L12 -> 0
T24: =+A14 -> 0
C27: Subscribed and sworn to before me this | Q27: =TODAY() -> 46083 | Y27: at Solano, Nueva Vizcaya,
A28: Philippines.
A30: OLIVER V. CATAHINA
A31: Municipal Civil Registrar
A32: Exempt from documentary stamp tax
A34: Municipal Form No. 92
A35: Republic of the Philippines
A36: Province of Nueva Vizcaya
A37: Municipality of Solano
A39: CONSENT TO MARRIAGE OF A PERSON UNDERAGE
A41: For FEMALE
A43: Municipality | F43: : | G43: SOLANO | Q43: Province | U43: : | V43: NUEVA VIZCAYA
B45: I/We | D45: =+APPLICATION!U30 -> 0 | L45: =+APPLICATION!AD30 -> 0 | S45: and | U45: n/a
A46: resident/s of | G46: =+APPLICATION!U34 -> 0
A47: =+APPLICATION!U31 -> 0 | G47: and | I47: n/a | O47: of | Q47: =+APPLICATION!U8 -> 0 | AA47: =+APPLICATION!U10 -> 0
A48: who is a resident of | H48: =+APPLICATION!U15 -> 0 | AA48: , | AB48: single, eighteen and
A49: less than twenty one years of age, after being duly sworn to in accordance with law do hereby state
A50: that I/we am/are freely giving my/our consent to my/our child/ward | W50: =+Q47 -> 0 | AD50: =+AA47 -> 0
A51: who is marrying with | I51: =+APPLICATION!B8 -> 0 | S51: =+APPLICATION!B10 -> 0 | Z51: who is presently residing
A52: in | B52: =+APPLICATION!B15 -> 0 | S52: . | T52: And that I/we know of no legal impediment
A53: to such marriage and swear to the correctness of the lawful age of my/our child/ward as stated in
...

Sheet ADVICE M
A1: Municipal Form No. 03 (Form No. 9)
A3: Republic of the Philippines
A4: Province of Nueva Vizcaya
A5: Municipality of Solano
A10: ADVICE UPON INTENDED MARRIAGE
A12: For MALE
A14: To : | C14: =+APPLICATION!B8 -> 0 | J14: =+APPLICATION!B10 -> 0
C16: My/our advice upon your intended marriage with | T16: =+APPLICATION!U8 -> 0 | AA16: =+APPLICATION!U10 -> 0
A17: as having been asked by you, and knowing that there is no legal impediment to this marriage,
A18: therefore I/we hereby give you this advice to marry her legally.
A20: Issued this | C20: Issued this | G20: =TODAY() -> 46083 | Q20: at Solano, Nueva Vizcaya, Philippines
T23: =+APPLICATION!B30 -> 0 | Z23: =+APPLICATION!L30 -> 0
T24: =+APPLICATION!B31 -> 0
C29: Subscribed and sworn to before me this | Q29: =G20 -> 46083 | AA29: at Solano, Nueva
A30: Vizcaya, Philippines.
A34: OLIVER V. CATAHINA
A35: Municipal Civil Registrar

Sheet ADVICE F
A1: Municipal Form No. 03 (Form No. 9)
A3: Republic of the Philippines
A4: Province of Nueva Vizcaya
A5: Municipality of Solano
A10: ADVICE UPON INTENDED MARRIAGE
A12: For FEMALE
A14: To : | C14: =+APPLICATION!U8 -> 0 | J14: =+APPLICATION!U10 -> 0
C16: My/our advice upon your intended marriage with | T16: =+APPLICATION!B8 -> 0 | AA16: =+APPLICATION!B10 -> 0
A17: as having been asked by you, and knowing that there is no legal impediment to this marriage,
A18: therefore I/we hereby give you this advice to marry him legally.
A20: Issued this | C20: Issued this | G20: =TODAY() -> 46083 | Q20: at Solano, Nueva Vizcaya, Philippines
T23: =+APPLICATION!U30 -> 0 | Z23: =+APPLICATION!AD30 -> 0
T24: =+APPLICATION!U31 -> 0
C29: Subscribed and sworn to before me this | Q29: =G20 -> 46083 | AA29: at Solano, Nueva
A30: Vizcaya, Philippines.
A34: OLIVER V. CATAHINA
A35: Municipal Civil Registrar

Sheet ADVICE M&F
A1: Municipal Form No. 03 (Form No. 9)
A3: Republic of the Philippines
A4: Province of Nueva Vizcaya
A5: Municipality of Solano
A9: ADVICE UPON INTENDED MARRIAGE
A11: For MALE
A13: To : | C13: =+APPLICATION!B8 -> 0 | J13: =+APPLICATION!B10 -> 0
C15: My/our advice upon your intended marriage with | T15: =+APPLICATION!U8 -> 0 | AA15: =+APPLICATION!U10 -> 0
A16: as having been asked by you, and knowing that there is no legal impediment to this marriage,
A17: therefore I/we hereby give you this advice to marry her legally.
A19: Issued this | C19: Issued this | G19: =TODAY() -> 46083 | Q19: at Solano, Nueva Vizcaya, Philippines
T22: =+APPLICATION!B30 -> 0 | Z22: =+APPLICATION!L30 -> 0
T23: =+APPLICATION!B31 -> 0
C27: Subscribed and sworn to before me this | Q27: =G19 -> 46083 | AA27: at Solano, Nueva
A28: Vizcaya, Philippines.
A32: OLIVER V. CATAHINA
A33: Municipal Civil Registrar
A36: Municipal Form No. 03 (Form No. 9)
A38: Republic of the Philippines
A39: Province of Nueva Vizcaya
A40: Municipality of Solano
A44: ADVICE UPON INTENDED MARRIAGE
A46: For FEMALE
A48: To : | C48: =+APPLICATION!U8 -> 0 | J48: =+APPLICATION!U10 -> 0
C50: My/our advice upon your intended marriage with | T50: =+APPLICATION!B8 -> 0 | AA50: =+APPLICATION!B10 -> 0
A51: as having been asked by you, and knowing that there is no legal impediment to this marriage,
A52: therefore I/we hereby give you this advice to marry him legally.
A54: Issued this | C54: Issued this | G54: =TODAY() -> 46083 | Q54: at Solano, Nueva Vizcaya, Philippines
T56: =+APPLICATION!U30 -> 0 | Z56: =+APPLICATION!AD30 -> 0
T57: =+APPLICATION!U31 -> 0
C61: Subscribed and sworn to before me this | Q61: =G54 -> 46083 | AA61: at Solano, Nueva
A62: Vizcaya, Philippines.
A66: OLIVER V. CATAHINA
A67: Municipal Civil Registrar

Sheet ADVICE M-CONSENT F
A1: Municipal Form No. 03 (Form No. 9)
A3: Republic of the Philippines
A4: Province of Nueva Vizcaya
A5: Municipality of Solano
A8: ADVICE UPON INTENDED MARRIAGE
A10: For MALE
A12: To : | C12: =+APPLICATION!B8 -> 0 | J12: =+APPLICATION!B10 -> 0
C14: My/our advice upon your intended marriage with | T14: =+APPLICATION!U8 -> 0 | AA14: =+APPLICATION!U10 -> 0
A15: as having been asked by you, and knowing that there is no legal impediment to this marriage,
A16: therefore I/we hereby give you this advice to marry her legally.
A18: Issued this | C18: Issued this | G18: =TODAY() -> 46083 | Q18: at Solano, Nueva Vizcaya, Philippines
T21: =+APPLICATION!B30 -> 0 | Z21: =+APPLICATION!L30 -> 0
T22: =+APPLICATION!B31 -> 0
C25: Subscribed and sworn to before me this | Q25: =G18 -> 46083 | AA25: at Solano, Nueva
A26: Vizcaya, Philippines.
A29: OLIVER V. CATAHINA
A30: Municipal Civil Registrar
A33: Municipal Form No. 92
A35: Republic of the Philippines
A36: Province of Nueva Vizcaya
A37: Municipality of Solano
A40: CONSENT TO MARRIAGE OF A PERSON UNDERAGE
A42: For FEMALE
A44: Municipality | F44: : | G44: SOLANO | Q44: Province | U44: : | V44: NUEVA VIZCAYA
B46: I/We | D46: =+APPLICATION!U30 -> 0 | L46: =+APPLICATION!AD30 -> 0 | S46: and | U46: n/a
A47: resident/s of | G47: =+APPLICATION!U34 -> 0
A48: =+APPLICATION!U31 -> 0 | G48: and | I48: n/a | O48: of | Q48: =+APPLICATION!U8 -> 0 | AA48: =+APPLICATION!U10 -> 0
A49: who is a resident of | H49: =+APPLICATION!U15 -> 0 | AA49: , | AB49: single, eighteen and
A50: less than twenty one years of age, after being duly sworn to in accordance with law do hereby state
A51: that I/we am/are freely giving my/our consent to my/our child/ward | W51: =+Q48 -> 0 | AD51: =+AA48 -> 0
A52: who is marrying with | I52: =+APPLICATION!B8 -> 0 | S52: =+APPLICATION!B10 -> 0 | Z52: who is presently residing
A53: in | B53: =+APPLICATION!B15 -> 0 | S53: . | T53: And that I/we know of no legal impediment
A54: to such marriage and swear to the correctness of the lawful age of my/our child/ward as stated in
A55: their application for their marriage license.
T58: =+D46 -> 0 | AB58: =+L46 -> 0
T59: =+A48 -> 0
C62: Subscribed and sworn to before me this | Q62: =TODAY() -> 46083 | Y62: at Solano, Nueva Vizcaya,
A63: Philippines.
A66: OLIVER V. CATAHINA
A67: Municipal Civil Registrar
...

Sheet CONSENT M-ADVICE F
A1: Municipal Form No. 92
A2: Republic of the Philippines
A3: Province of Nueva Vizcaya
A4: Municipality of Solano
A6: CONSENT TO MARRIAGE OF A PERSON UNDERAGE
A8: For MALE
A10: Municipality | F10: : | G10: SOLANO | Q10: Province | U10: : | V10: NUEVA VIZCAYA
B12: I/We | D12: =+APPLICATION!B30 -> 0 | L12: =+APPLICATION!L30 -> 0 | S12: and | U12: n/a
A13: resident/s of | G13: =+APPLICATION!B34 -> 0
A14: =+APPLICATION!B31 -> 0 | G14: and | I14: n/a | O14: of | Q14: =+APPLICATION!B8 -> 0 | Z14: =+APPLICATION!B10 -> 0
A15: who is a resident of | I15: =+APPLICATION!B15 -> 0 | AA15: , | AB15: single, eighteen and
A16: less than twenty one years of age, after being duly sworn to in accordance with law do hereby state
A17: that I/we am/are freely giving my/our consent to my/our child/ward | W17: =+Q14 -> 0 | AC17: =+Z14 -> 0
A18: who is marrying with | I18: =+APPLICATION!U8 -> 0 | R18: =+APPLICATION!U10 -> 0 | Z18: who is presently residing
A19: in | B19: =+APPLICATION!U15 -> 0 | S19: . | T19: And that I/we know of no legal impediment
A20: to such marriage and swear to the correctness of the lawful age of my/our child/ward as stated in
A21: their application for their marriage license.
T24: =+D12 -> 0 | AB24: =+L12 -> 0
T25: =+A14 -> 0
C28: Subscribed and sworn to before me this | Q28: =TODAY() -> 46083 | Y28: at Solano, Nueva Vizcaya,
A29: Philippines.
A32: OLIVER V. CATAHINA
A33: Municipal Civil Registrar
A34: Exempt from documentary stamp tax
A36: Municipal Form No. 03 (Form No. 9)
A37: Republic of the Philippines
A38: Province of Nueva Vizcaya
A39: Municipality of Solano
A41: ADVICE UPON INTENDED MARRIAGE
A43: For FEMALE
A45: To : | C45: =+APPLICATION!U8 -> 0 | J45: =+APPLICATION!U10 -> 0
C47: My/our advice upon your intended marriage with | T47: =+APPLICATION!B8 -> 0 | AA47: =+APPLICATION!B10 -> 0
A48: as having been asked by you, and knowing that there is no legal impediment to this marriage,
A49: therefore I/we hereby give you this advice to marry him legally.
A51: Issued this | C51: Issued this | G51: =TODAY() -> 46083 | Q51: at Solano, Nueva Vizcaya, Philippines
T53: =+APPLICATION!U30 -> 0 | Z53: =+APPLICATION!AD30 -> 0
T54: =+APPLICATION!U31 -> 0
T55: Solano LGU Employee No. 1999081603
C57: Subscribed and sworn to before me this | Q57: =G51 -> 46083 | AA57: at Solano, Nueva
A58: Vizcaya, Philippines.
...

Sheet Notice
A1: Mun. Form No. 9
A3: Republic of the Philippines
A4: OFFICE OF THE MUNICIPAL CIVIL REGISTRAR
A5: Solano, Nueva Vizcaya
A8: N O T I C E
A9: APPLICANTS FOR MARRIAGE LICENSE
A12: =+APPLICATION!B8 -> 0 | I12: =+APPLICATION!B10 -> 0
A14: and
A16: =+APPLICATION!U8 -> 0 | I16: =+APPLICATION!U10 -> 0
A19: Name | E19: : | F19: =A12 -> 0 | M19: =I12 -> 0 | T19: Age | W19: : | X19: =+APPLICATION!N11 -> 0
A20: Birthplace | E20: : | F20: =+APPLICATION!B12 -> 0 | T20: Father | W20: : | X20: =+APPLICATION!B22 -> 0 | AB20: =+APPLICATION!L22 -> 0
A21: Residence | E21: : | F21: =+APPLICATION!B15 -> 0 | T21: Mother | W21: : | X21: =+APPLICATION!B26 -> 0 | AB21: =+APPLICATION!K26 -> 0
A23: Wishes to contract marriage with
A25: Name | E25: : | F25: =+A16 -> 0 | M25: =+I16 -> 0 | T25: Age | W25: : | X25: =+APPLICATION!AF11 -> 0
A26: Birthplace | E26: : | F26: =+APPLICATION!U12 -> 0 | T26: Father | W26: : | X26: =+APPLICATION!U22 -> 0 | AB26: =+APPLICATION!AC22 -> 0
A27: Residence | E27: : | F27: =+APPLICATION!U15 -> 0 | T27: Mother | W27: : | X27: =+APPLICATION!U26 -> 0 | AB27: =+APPLICATION!AD26 -> 0
A29: Any person having knowledge of any legal impediment to such marriage will please report to this Office
A30: within ten (10) days from this date.
A32: =+APPLICATION!B37 -> 0 | B32: =+APPLICATION!E37 -> 0 | F32: =+APPLICATION!L37 -> 0 | V32: Application Number : | AB32: =+APPLICATION!X3 -> 2026 | AE32: - | AF32: =+APPLICATION!AD3 -> 0
C33: Date
V35: OLIVER V. CATAHINA
V36: Municipal Civil Registrar
A37: Application/Notice Prepared by :
A40: =+APPLICATION!F4 -> BERNADETTE T. SAMANDRE
A41: Registration Officer II
A43: Copy Furnished :
A44: - | B44: L.C.R. | E44: =+F26 -> 0
A45: - | B45: L.C.R.
A46: - | B46: L.C.R.
A47: - | B47: File
A49: Note: This notice shall request all persons having knowledge of any impediment to the marriage to advise the
A50: Local Civil Registrar thereof. The license shall be issued after completion of the publication, unless the LCR
A51: receives information of any alleged impediment to the marriage. (RA 366 Art. 63)

Sheet AddressBACKnotice
A1: OLIVER V. CATAHINA | T1: CENSUS MAIL FREE
A2: Municipal Civil Registrar | T2: Pursuant to RA 265
A3: Solano, Nueva Vizcaya
A4: 3709
A7: THE LOCAL CIVIL REGISTRAR
A8: Local Registrar's Office
A9: =+Notice!E44 -> 0

Sheet EnvelopeAddress
A1: OLIVER V. CATAHINA | O1: CENSUS MAIL FREE
A2: Municipal Civil Registrar | O2: Pursuant to RA 265
A3: Solano, Nueva Vizcaya
A4: 3709
A7: THE LOCAL CIVIL REGISTRAR
A8: Local Civil Registrar's Office
A9: =+Notice!E44 -> 0
