Workbook

Sheet APPLICATION
G2: Nueva Vizcaya
G3: Solano | X3: 2026 | AC3: - | AD3: 17
F4: BERNADETTE T. SAMANDRE
F5: 4 | G5: February | L5: 2026
A6: =+U8 -> 0 | F6: =+U9 -> 0 | H6: =+U10 -> 0 | R6: =+B8 -> 0 | V6: =+B9 -> 0 | Y6: =+B10 -> 0
B18: N/A | U18: N/A
B21: None | U21: None
L22: =+B10 -> 0 | AC22: =+U10 -> 0
B23: =+H13 -> 0 | U23: =+Z13 -> 0
B25: =+B15 -> 0 | U25: =+U15 -> 0 | AF25: =+AF15 -> 0
K26: =+B9 -> 0 | AD26: =+U9 -> 0
B27: =+H13 -> 0
B29: =+B15 -> 0 | U29: =+U25 -> 0 | AF29: =+AF25 -> 0
H30: =+K26 -> 0 | L30: =+L22 -> 0 | Y30: =+AD26 -> 0 | AD30: =+AC22 -> 0
B34: =+B29 -> 0 | U34: =+U29 -> 0 | AF34: =+AF29 -> 0
U37: =+B37 -> 0 | W37: =+E37 -> 0 | AD37: =+L37 -> 0
B38: Solano, Nueva Vizcaya | U38: Solano, Nueva Vizcaya
D39: National ID 4091-6805-3082-4958 | V39: National ID 4618-6358-2391-7683
B42: OLIVER V. CATAHINA | U42: OLIVER V. CATAHINA

Sheet ADVICE M-CONSENT F
A1: Municipal Form No. 03 (Form No. 9)
A3: Republic of the Philippines
A4: Province of Nueva Vizcaya
A5: Municipality of Solano
A8: ADVICE UPON INTENDED MARRIAGE
A10: For MALE
A12: To : | C12: =+APPLICATION!B8 -> 0 | J12: =+APPLICATION!B10 -> 0
C14: My/our advice upon your intended marriage with | T14: =+APPLICATION!U8 -> 0 | AA14: =+APPLICATION!U10 -> 0
A15: as having been asked by you, and knowing that there is no legal impediment to this marriage,
A16: therefore I/we hereby give you this advice to marry her legally.
A18: Issued this | C18: Issued this | G18: =TODAY() -> 46061 | Q18: at Solano, Nueva Vizcaya, Philippines
T21: =+APPLICATION!B30 -> 0 | Z21: =+APPLICATION!L30 -> 0
T22: =+APPLICATION!B31 -> 0
T23: VIN: 5013-0106A-K0490MED20000
C25: Subscribed and sworn to before me this | Q25: =G18 -> 46061 | AA25: at Solano, Nueva
A26: Vizcaya, Philippines.
A29: OLIVER V. CATAHINA
A30: Municipal Civil Registrar
A33: Municipal Form No. 92
A35: Republic of the Philippines
A36: Province of Nueva Vizcaya
A37: Municipality of Solano
A40: CONSENT TO MARRIAGE OF A PERSON UNDERAGE
A42: For FEMALE
A44: Municipality | F44: : | G44: SOLANO | Q44: Province | U44: : | V44: NUEVA VIZCAYA
B46: I/We | D46: =+APPLICATION!U30 -> 0 | L46: =+APPLICATION!AD30 -> 0 | S46: and | U46: n/a
A47: resident/s of | G47: =+APPLICATION!U34 -> 0
A48: =+APPLICATION!U31 -> 0 | G48: and | I48: n/a | O48: of | Q48: =+APPLICATION!U8 -> 0 | AA48: =+APPLICATION!U10 -> 0
A49: who is a resident of | H49: =+APPLICATION!U15 -> 0 | AA49: , | AB49: single, eighteen and
A50: less than twenty one years of age, after being duly sworn to in accordance with law do hereby state
A51: that I/we am/are freely giving my/our consent to my/our child/ward | W51: =+Q48 -> 0 | AD51: =+AA48 -> 0
A52: who is marrying with | I52: =+APPLICATION!B8 -> 0 | S52: =+APPLICATION!B10 -> 0 | Z52: who is presently residing
A53: in | B53: =+APPLICATION!B15 -> 0 | S53: . | T53: And that I/we know of no legal impediment
A54: to such marriage and swear to the correctness of the lawful age of my/our child/ward as stated in
A55: their application for their marriage license.
T58: =+D46 -> 0 | AB58: =+L46 -> 0
T59: =+A48 -> 0
T60: TIN: 495-486-852-000
C62: Subscribed and sworn to before me this | Q62: =TODAY() -> 46061 | Y62: at Solano, Nueva Vizcaya,
A63: Philippines.
...

Sheet AddressBACKNotice
A1: OLIVER V. CATAHINA | T1: CENSUS MAIL FREE
A2: Municipal Civil Registrar | T2: Pursuant to RA 265
A3: Solano, Nueva Vizcaya
A4: 3709
A7: THE LOCAL CIVIL REGISTRAR
A8: Local Registrar's Office
A9: =+NOTICE!E44 -> 0

Sheet EnvelopeAddress
A1: OLIVER V. CATAHINA | O1: CENSUS MAIL FREE
A2: Municipal Civil Registrar | O2: Pursuant to RA 265
A3: Solano, Nueva Vizcaya
A4: 3709
A7: THE LOCAL CIVIL REGISTRAR
A8: Local Civil Registrar's Office
A9: =+NOTICE!E44 -> 0

Sheet NOTICE
A1: Mun. Form No. 9
A3: Republic of the Philippines
A4: OFFICE OF THE MUNICIPAL CIVIL REGISTRAR
A5: Solano, Nueva Vizcaya
A8: N O T I C E
A9: APPLICANTS FOR MARRIAGE LICENSE
A12: =+APPLICATION!B8 -> 0 | I12: =+APPLICATION!B10 -> 0
A14: and
A16: =+APPLICATION!U8 -> 0 | I16: =+APPLICATION!U10 -> 0
A19: Name | E19: : | F19: =A12 -> 0 | M19: =I12 -> 0 | T19: Age | W19: : | X19: =+APPLICATION!N11 -> 0
A20: Birthplace | E20: : | F20: =+APPLICATION!B12 -> 0 | T20: Father | W20: : | X20: =+APPLICATION!B22 -> 0 | AB20: =+APPLICATION!L22 -> 0
A21: Residence | E21: : | F21: =+APPLICATION!B15 -> 0 | T21: Mother | W21: : | X21: =+APPLICATION!B26 -> 0 | AB21: =+APPLICATION!AD26 -> 0
A23: Wishes to contract marriage with
A25: Name | E25: : | F25: =+A16 -> 0 | M25: =+I16 -> 0 | T25: Age | W25: : | X25: =+APPLICATION!AF11 -> 0
A26: Birthplace | E26: : | F26: =+APPLICATION!U12 -> 0 | T26: Father | W26: : | X26: =+APPLICATION!U22 -> 0 | AB26: =+APPLICATION!AC22 -> 0
A27: Residence | E27: : | F27: =+APPLICATION!U15 -> 0 | T27: Mother | W27: : | X27: =+APPLICATION!U26 -> 0 | AB27: =+APPLICATION!AD26 -> 0
A29: Any person having knowledge of any legal impediment to such marriage will please report to this Office
A30: within ten (10) days from this date.
A32: =+APPLICATION!B37 -> 0 | B32: =+APPLICATION!E37 -> 0 | F32: =+APPLICATION!L37 -> 0 | V32: Application Number : | AB32: =+APPLICATION!X3 -> 2026 | AE32: - | AF32: =+APPLICATION!AD3 -> 17
C33: Date | F33: =+APPLICATION!L38 -> 0
V35: OLIVER V. CATAHINA
V36: Municipal Civil Registrar
A37: Application/Notice Prepared by :
A40: =+APPLICATION!F4 -> BERNADETTE T. SAMANDRE
A41: Registration Officer II
A43: Copy Furnished :
A44: - | B44: L.C.R. | E44: =+F26 -> 0
A45: - | B45: L.C.R.
A46: - | B46: L.C.R.
A47: - | B47: File
A49: Note: This notice shall request all persons having knowledge of any impediment to the marriage to advise the
A50: Local Civil Registrar thereof. The license shall be issued after completion of the publication, unless the LCR
A51: receives information of any alleged impediment to the marriage. (RA 366 Art. 63)
