Workbook

Sheet CONSENT M&F
A1: Municipal Form No. 92
A2: Republic of the Philippines
A3: Province of Nueva Vizcaya
A4: Municipality of Solano
A6: CONSENT TO MARRIAGE OF A PERSON UNDERAGE
A8: For MALE
A10: Municipality | F10: : | G10: SOLANO | Q10: Province | U10: : | V10: NUEVA VIZCAYA
B12: I/We | D12: =+APPLICATION!B30 -> 0 | L12: =+APPLICATION!L30 -> 0 | S12: and | U12: n/a
A13: resident/s of | G13: =+APPLICATION!B34 -> 0
A14: =+APPLICATION!B31 -> 0 | G14: and | I14: n/a | O14: of | Q14: =+APPLICATION!B8 -> 0 | Z14: =+APPLICATION!B10 -> 0
A15: who is a resident of | I15: =+APPLICATION!B34 -> 0 | AA15: , | AB15: single, eighteen and
A16: less than twenty one years of age, after being duly sworn to in accordance with law do hereby state
A17: that I/we am/are freely giving my/our consent to my/our child/ward | W17: =+Q14 -> 0 | AC17: =+Z14 -> 0
A18: who is marrying with | I18: =+APPLICATION!U8 -> 0 | R18: =+APPLICATION!U10 -> 0 | Z18: who is presently residing
A19: in | B19: =+APPLICATION!U15 -> 0 | S19: . | T19: And that I/we know of no legal impediment
A20: to such marriage and swear to the correctness of the lawful age of my/our child/ward as stated in
A21: their application for their marriage license.
T23: =+D12 -> 0 | AB23: =+L12 -> 0
T24: =+A14 -> 0
T25: National ID 4167-4290-5893-5139
C27: Subscribed and sworn to before me this | Q27: =TODAY() -> 46061 | Y27: at Solano, Nueva Vizcaya,
A28: Philippines.
A30: OLIVER V. CATAHINA
A31: Municipal Civil Registrar
A32: Exempt from documentary stamp tax
A34: Municipal Form No. 92
A35: Republic of the Philippines
A36: Province of Nueva Vizcaya
A37: Municipality of Solano
A39: CONSENT TO MARRIAGE OF A PERSON UNDERAGE
A41: For FEMALE
A43: Municipality | F43: : | G43: SOLANO | Q43: Province | U43: : | V43: NUEVA VIZCAYA
B45: I/We | D45: =+APPLICATION!U30 -> 0 | L45: =+APPLICATION!AD30 -> 0 | S45: and | U45: n/a
A46: resident/s of | G46: =+APPLICATION!U34 -> 0
A47: =+APPLICATION!U31 -> 0 | G47: and | I47: n/a | O47: of | Q47: =+APPLICATION!U8 -> 0 | AA47: =+APPLICATION!U10 -> 0
A48: who is a resident of | H48: =+APPLICATION!U34 -> 0 | AA48: , | AB48: single, eighteen and
A49: less than twenty one years of age, after being duly sworn to in accordance with law do hereby state
A50: that I/we am/are freely giving my/our consent to my/our child/ward | W50: =+Q47 -> 0 | AD50: =+AA47 -> 0
A51: who is marrying with | I51: =+APPLICATION!B8 -> 0 | S51: =+APPLICATION!B10 -> 0 | Z51: who is presently residing
A52: in | B52: =+APPLICATION!B15 -> 0 | S52: . | T52: And that I/we know of no legal impediment
...

Sheet APPLICATION
G2: Nueva Vizcaya
G3: Solano | X3: 2026 | AC3: - | AD3: 17
F4: BERNADETTE T. SAMANDRE
F5: 4 | G5: February | L5: 2026
A6: =+U8 -> 0 | F6: =+U9 -> 0 | H6: =+U10 -> 0 | R6: =+B8 -> 0 | V6: =+B9 -> 0 | Y6: =+B10 -> 0
B18: N/A | U18: N/A
B21: None | U21: None
L22: =+B10 -> 0 | AC22: =+U10 -> 0
B23: =+H13 -> 0 | U23: =+Z13 -> 0
B25: =+B15 -> 0 | U25: =+U15 -> 0 | AF25: =+AF15 -> 0
K26: =+B9 -> 0 | AD26: =+U9 -> 0
B27: =+H13 -> 0
B29: =+B15 -> 0 | U29: =+U25 -> 0 | AF29: =+AF25 -> 0
H30: =+K26 -> 0 | L30: =+L22 -> 0 | Y30: =+AD26 -> 0 | AD30: =+AC22 -> 0
B34: =+B29 -> 0 | U34: =+U29 -> 0 | AF34: =+AF29 -> 0
U37: =+B37 -> 0 | W37: =+E37 -> 0 | AD37: =+L37 -> 0
B38: Solano, Nueva Vizcaya | U38: Solano, Nueva Vizcaya
D39: National ID 4091-6805-3082-4958 | V39: National ID 4618-6358-2391-7683
B42: OLIVER V. CATAHINA | U42: OLIVER V. CATAHINA

Sheet AddressBACKNotice
A1: OLIVER V. CATAHINA | T1: CENSUS MAIL FREE
A2: Municipal Civil Registrar | T2: Pursuant to RA 265
A3: Solano, Nueva Vizcaya
A4: 3709
A7: THE LOCAL CIVIL REGISTRAR
A8: Local Registrar's Office
A9: =+NOTICE!E44 -> 0

Sheet EnvelopeAddress
A1: OLIVER V. CATAHINA | O1: CENSUS MAIL FREE
A2: Municipal Civil Registrar | O2: Pursuant to RA 265
A3: Solano, Nueva Vizcaya
A4: 3709
A7: THE LOCAL CIVIL REGISTRAR
A8: Local Civil Registrar's Office
A9: =+NOTICE!E44 -> 0

Sheet NOTICE
A1: Mun. Form No. 9
A3: Republic of the Philippines
A4: OFFICE OF THE MUNICIPAL CIVIL REGISTRAR
A5: Solano, Nueva Vizcaya
A8: N O T I C E
A9: APPLICANTS FOR MARRIAGE LICENSE
A12: =+APPLICATION!B8 -> 0 | I12: =+APPLICATION!B10 -> 0
A14: and
A16: =+APPLICATION!U8 -> 0 | I16: =+APPLICATION!U10 -> 0
A19: Name | E19: : | F19: =A12 -> 0 | M19: =I12 -> 0 | T19: Age | W19: : | X19: =+APPLICATION!N11 -> 0
A20: Birthplace | E20: : | F20: =+APPLICATION!B12 -> 0 | T20: Father | W20: : | X20: =+APPLICATION!B22 -> 0 | AB20: =+APPLICATION!L22 -> 0
A21: Residence | E21: : | F21: =+APPLICATION!B15 -> 0 | T21: Mother | W21: : | X21: =+APPLICATION!B26 -> 0 | AB21: =+APPLICATION!K26 -> 0
A23: Wishes to contract marriage with
A25: Name | E25: : | F25: =+A16 -> 0 | M25: =+I16 -> 0 | T25: Age | W25: : | X25: =+APPLICATION!AF11 -> 0
A26: Birthplace | E26: : | F26: =+APPLICATION!U12 -> 0 | T26: Father | W26: : | X26: =+APPLICATION!U22 -> 0 | AB26: =+APPLICATION!AC22 -> 0
A27: Residence | E27: : | F27: =+APPLICATION!U15 -> 0 | T27: Mother | W27: : | X27: =+APPLICATION!U26 -> 0 | AB27: =+APPLICATION!AD26 -> 0
A29: Any person having knowledge of any legal impediment to such marriage will please report to this Office
A30: within ten (10) days from this date.
A32: =+APPLICATION!B37 -> 0 | B32: =+APPLICATION!E37 -> 0 | F32: =+APPLICATION!L37 -> 0 | V32: Application Number : | AB32: =+APPLICATION!X3 -> 2026 | AE32: - | AF32: =+APPLICATION!AD3 -> 17
C33: Date
V35: OLIVER V. CATAHINA
V36: Municipal Civil Registrar
A37: Application/Notice Prepared by :
A40: =+APPLICATION!F4 -> BERNADETTE T. SAMANDRE
A41: Registration Officer II
A43: Copy Furnished :
A44: - | B44: L.C.R. | E44: =+F26 -> 0
A45: - | B45: L.C.R.
A46: - | B46: L.C.R.
A47: - | B47: File
A49: Note: This notice shall request all persons having knowledge of any impediment to the marriage to advise the
A50: Local Civil Registrar thereof. The license shall be issued after completion of the publication, unless the LCR
A51: receives information of any alleged impediment to the marriage. (RA 366 Art. 63)
